Traceback (most recent call last):
  File "/opt/hostedtoolcache/Python/3.8.13/x64/lib/python3.8/site-packages/jupyter_cache/executors/utils.py", line 51, in single_nb_execution
    executenb(
  File "/opt/hostedtoolcache/Python/3.8.13/x64/lib/python3.8/site-packages/nbclient/client.py", line 1204, in execute
    return NotebookClient(nb=nb, resources=resources, km=km, **kwargs).execute()
  File "/opt/hostedtoolcache/Python/3.8.13/x64/lib/python3.8/site-packages/nbclient/util.py", line 84, in wrapped
    return just_run(coro(*args, **kwargs))
  File "/opt/hostedtoolcache/Python/3.8.13/x64/lib/python3.8/site-packages/nbclient/util.py", line 62, in just_run
    return loop.run_until_complete(coro)
  File "/opt/hostedtoolcache/Python/3.8.13/x64/lib/python3.8/asyncio/base_events.py", line 616, in run_until_complete
    return future.result()
  File "/opt/hostedtoolcache/Python/3.8.13/x64/lib/python3.8/site-packages/nbclient/client.py", line 663, in async_execute
    await self.async_execute_cell(
  File "/opt/hostedtoolcache/Python/3.8.13/x64/lib/python3.8/site-packages/nbclient/client.py", line 965, in async_execute_cell
    await self._check_raise_for_error(cell, cell_index, exec_reply)
  File "/opt/hostedtoolcache/Python/3.8.13/x64/lib/python3.8/site-packages/nbclient/client.py", line 862, in _check_raise_for_error
    raise CellExecutionError.from_cell_and_msg(cell, exec_reply_content)
nbclient.exceptions.CellExecutionError: An error occurred while executing the following cell:
------------------
import matplotlib.pyplot as plt
from graphbook_code import heatmap, cmaps
import seaborn as sns

def rm_ticks(ax, x=False, y=False, **kwargs):
    if x is not None:
        ax.axes.xaxis.set_visible(x)
    if y is not None:
        ax.axes.yaxis.set_visible(y)
    sns.despine(ax=ax, **kwargs)

fig = plt.figure();

# adjacency matrices
perturbed_points = {5, 6}
for i in range(time_points):
    if i not in perturbed_points:
        ax = fig.add_axes([.02*i, -.02*i, .8, .8])
    else:
        ax = fig.add_axes([.02*i+.8, -.02*i, .8, .8])
    ax = heatmap(networks[i], ax=ax, cbar=False)
    if i == 0:
        ax.set_title("Ten Normal Time Points", loc="left", fontsize=16)
    if i == 5:
        ax.set_title("Two Perturbed Time Points", loc="left", fontsize=16)
    rm_ticks(ax, top=False, right=False)
    
plt.figtext(1, -.3, "Figure 8.1")
fig.suptitle("Network Timeseries Data", fontsize=24, x=1);
------------------

[0;31m---------------------------------------------------------------------------[0m
[0;31mNameError[0m                                 Traceback (most recent call last)
Input [0;32mIn [2][0m, in [0;36m<cell line: 16>[0;34m()[0m
[1;32m     14[0m [38;5;66;03m# adjacency matrices[39;00m
[1;32m     15[0m perturbed_points [38;5;241m=[39m {[38;5;241m5[39m, [38;5;241m6[39m}
[0;32m---> 16[0m [38;5;28;01mfor[39;00m i [38;5;129;01min[39;00m [38;5;28mrange[39m([43mtime_points[49m):
[1;32m     17[0m     [38;5;28;01mif[39;00m i [38;5;129;01mnot[39;00m [38;5;129;01min[39;00m perturbed_points:
[1;32m     18[0m         ax [38;5;241m=[39m fig[38;5;241m.[39madd_axes([[38;5;241m.02[39m[38;5;241m*[39mi, [38;5;241m-[39m[38;5;241m.02[39m[38;5;241m*[39mi, [38;5;241m.8[39m, [38;5;241m.8[39m])

[0;31mNameError[0m: name 'time_points' is not defined
NameError: name 'time_points' is not defined

