Traceback (most recent call last):
  File "/opt/hostedtoolcache/Python/3.8.12/x64/lib/python3.8/site-packages/jupyter_cache/executors/utils.py", line 51, in single_nb_execution
    executenb(
  File "/opt/hostedtoolcache/Python/3.8.12/x64/lib/python3.8/site-packages/nbclient/client.py", line 1093, in execute
    return NotebookClient(nb=nb, resources=resources, km=km, **kwargs).execute()
  File "/opt/hostedtoolcache/Python/3.8.12/x64/lib/python3.8/site-packages/nbclient/util.py", line 84, in wrapped
    return just_run(coro(*args, **kwargs))
  File "/opt/hostedtoolcache/Python/3.8.12/x64/lib/python3.8/site-packages/nbclient/util.py", line 62, in just_run
    return loop.run_until_complete(coro)
  File "/opt/hostedtoolcache/Python/3.8.12/x64/lib/python3.8/asyncio/base_events.py", line 616, in run_until_complete
    return future.result()
  File "/opt/hostedtoolcache/Python/3.8.12/x64/lib/python3.8/site-packages/nbclient/client.py", line 559, in async_execute
    await self.async_execute_cell(
  File "/opt/hostedtoolcache/Python/3.8.12/x64/lib/python3.8/site-packages/nbclient/client.py", line 854, in async_execute_cell
    self._check_raise_for_error(cell, exec_reply)
  File "/opt/hostedtoolcache/Python/3.8.12/x64/lib/python3.8/site-packages/nbclient/client.py", line 756, in _check_raise_for_error
    raise CellExecutionError.from_cell_and_msg(cell, exec_reply_content)
nbclient.exceptions.CellExecutionError: An error occurred while executing the following cell:
------------------
### its broken weeeeeeeeee
### test code block

from graspologic.simulations import rdpg
import numpy as np
from graspologic.embed import OmnibusEmbed as OMNI


X = np.random.uniform(.2, .8, size=(100, 1))
A = rdpg(X)
B = rdpg(X)

def get_statistic(adjacencies, return_latents=False):
    """
    Get the operator norm of the difference of two matrices.
    """
    omni = OMNI(n_components=2)
    latents_est = omni.fit_transform(adjacencies)
    X, Y = latents_est[0], latents_est[1]
    y = np.linalg.norm(X - Y, ord=2)
    if return_latents:
        return y, X
    else:
        return y

latents = omni.fit_transform([A, B])

ys_same = []
for i in range(1000):
    A_, B_ = rdpg(latents[0]), rdpg(latents[0])
    y_ = get_statistic([A_, B_])
    ys_same.append(y_)
    
ys_diff = []
for i in range(1000):
    A_, B_ = rdpg(latents[0]), rdpg(latents[1])
    y_ = get_statistic([A_, B_])
    ys_diff.append(y_)
------------------

[0;31m---------------------------------------------------------------------------[0m
[0;31mNameError[0m                                 Traceback (most recent call last)
[0;32m/tmp/ipykernel_2107/1795371384.py[0m in [0;36m<module>[0;34m[0m
[1;32m     24[0m         [0;32mreturn[0m [0my[0m[0;34m[0m[0;34m[0m[0m
[1;32m     25[0m [0;34m[0m[0m
[0;32m---> 26[0;31m [0mlatents[0m [0;34m=[0m [0momni[0m[0;34m.[0m[0mfit_transform[0m[0;34m([0m[0;34m[[0m[0mA[0m[0;34m,[0m [0mB[0m[0;34m][0m[0;34m)[0m[0;34m[0m[0;34m[0m[0m
[0m[1;32m     27[0m [0;34m[0m[0m
[1;32m     28[0m [0mys_same[0m [0;34m=[0m [0;34m[[0m[0;34m][0m[0;34m[0m[0;34m[0m[0m

[0;31mNameError[0m: name 'omni' is not defined
NameError: name 'omni' is not defined

