Traceback (most recent call last):
  File "/opt/hostedtoolcache/Python/3.8.13/x64/lib/python3.8/site-packages/jupyter_cache/executors/utils.py", line 51, in single_nb_execution
    executenb(
  File "/opt/hostedtoolcache/Python/3.8.13/x64/lib/python3.8/site-packages/nbclient/client.py", line 1204, in execute
    return NotebookClient(nb=nb, resources=resources, km=km, **kwargs).execute()
  File "/opt/hostedtoolcache/Python/3.8.13/x64/lib/python3.8/site-packages/nbclient/util.py", line 84, in wrapped
    return just_run(coro(*args, **kwargs))
  File "/opt/hostedtoolcache/Python/3.8.13/x64/lib/python3.8/site-packages/nbclient/util.py", line 62, in just_run
    return loop.run_until_complete(coro)
  File "/opt/hostedtoolcache/Python/3.8.13/x64/lib/python3.8/asyncio/base_events.py", line 616, in run_until_complete
    return future.result()
  File "/opt/hostedtoolcache/Python/3.8.13/x64/lib/python3.8/site-packages/nbclient/client.py", line 663, in async_execute
    await self.async_execute_cell(
  File "/opt/hostedtoolcache/Python/3.8.13/x64/lib/python3.8/site-packages/nbclient/client.py", line 965, in async_execute_cell
    await self._check_raise_for_error(cell, cell_index, exec_reply)
  File "/opt/hostedtoolcache/Python/3.8.13/x64/lib/python3.8/site-packages/nbclient/client.py", line 862, in _check_raise_for_error
    raise CellExecutionError.from_cell_and_msg(cell, exec_reply_content)
nbclient.exceptions.CellExecutionError: An error occurred while executing the following cell:
------------------
from graspologic.embed import MultipleASE
from graspologic.cluster import KMeansClustertoGMMCluster

embedding = MultipleASE().fit_transform(As)
labels = AutoGMMCluster(max_components=10).fit_predict(embedding)
------------------

[0;31m---------------------------------------------------------------------------[0m
[0;31mImportError[0m                               Traceback (most recent call last)
Input [0;32mIn [3][0m, in [0;36m<cell line: 2>[0;34m()[0m
[1;32m      1[0m [38;5;28;01mfrom[39;00m [38;5;21;01mgraspologic[39;00m[38;5;21;01m.[39;00m[38;5;21;01membed[39;00m [38;5;28;01mimport[39;00m MultipleASE
[0;32m----> 2[0m [38;5;28;01mfrom[39;00m [38;5;21;01mgraspologic[39;00m[38;5;21;01m.[39;00m[38;5;21;01mcluster[39;00m [38;5;28;01mimport[39;00m KMeansClustertoGMMCluster
[1;32m      4[0m embedding [38;5;241m=[39m MultipleASE()[38;5;241m.[39mfit_transform(As)
[1;32m      5[0m labels [38;5;241m=[39m AutoGMMCluster(max_components[38;5;241m=[39m[38;5;241m10[39m)[38;5;241m.[39mfit_predict(embedding)

[0;31mImportError[0m: cannot import name 'KMeansClustertoGMMCluster' from 'graspologic.cluster' (/opt/hostedtoolcache/Python/3.8.13/x64/lib/python3.8/site-packages/graspologic/cluster/__init__.py)
ImportError: cannot import name 'KMeansClustertoGMMCluster' from 'graspologic.cluster' (/opt/hostedtoolcache/Python/3.8.13/x64/lib/python3.8/site-packages/graspologic/cluster/__init__.py)

