Traceback (most recent call last):
  File "/opt/hostedtoolcache/Python/3.8.13/x64/lib/python3.8/site-packages/jupyter_cache/executors/utils.py", line 51, in single_nb_execution
    executenb(
  File "/opt/hostedtoolcache/Python/3.8.13/x64/lib/python3.8/site-packages/nbclient/client.py", line 1204, in execute
    return NotebookClient(nb=nb, resources=resources, km=km, **kwargs).execute()
  File "/opt/hostedtoolcache/Python/3.8.13/x64/lib/python3.8/site-packages/nbclient/util.py", line 84, in wrapped
    return just_run(coro(*args, **kwargs))
  File "/opt/hostedtoolcache/Python/3.8.13/x64/lib/python3.8/site-packages/nbclient/util.py", line 62, in just_run
    return loop.run_until_complete(coro)
  File "/opt/hostedtoolcache/Python/3.8.13/x64/lib/python3.8/asyncio/base_events.py", line 616, in run_until_complete
    return future.result()
  File "/opt/hostedtoolcache/Python/3.8.13/x64/lib/python3.8/site-packages/nbclient/client.py", line 663, in async_execute
    await self.async_execute_cell(
  File "/opt/hostedtoolcache/Python/3.8.13/x64/lib/python3.8/site-packages/nbclient/client.py", line 965, in async_execute_cell
    await self._check_raise_for_error(cell, cell_index, exec_reply)
  File "/opt/hostedtoolcache/Python/3.8.13/x64/lib/python3.8/site-packages/nbclient/client.py", line 862, in _check_raise_for_error
    raise CellExecutionError.from_cell_and_msg(cell, exec_reply_content)
nbclient.exceptions.CellExecutionError: An error occurred while executing the following cell:
------------------
import matplotlib.pyplot as plt
import seaborn as sns
import matplotlib.image as mpimg

coords_df["Community"] = labels
coords_df['Community'] = coords_df['Community'].astype('category')
fig, axs = plt.subplots(1, 2, figsize=(18, 6))
axs[0].imshow(mpimg.imread('./Images/lobes.png'))
axs[0].set_axis_off()
sns.scatterplot(x="y", y="z", data=coords_df, hue="Community", ax=axs[1]);
------------------

[0;31m---------------------------------------------------------------------------[0m
[0;31mFileNotFoundError[0m                         Traceback (most recent call last)
Input [0;32mIn [6][0m, in [0;36m<cell line: 8>[0;34m()[0m
[1;32m      6[0m coords_df[[38;5;124m'[39m[38;5;124mCommunity[39m[38;5;124m'[39m] [38;5;241m=[39m coords_df[[38;5;124m'[39m[38;5;124mCommunity[39m[38;5;124m'[39m][38;5;241m.[39mastype([38;5;124m'[39m[38;5;124mcategory[39m[38;5;124m'[39m)
[1;32m      7[0m fig, axs [38;5;241m=[39m plt[38;5;241m.[39msubplots([38;5;241m1[39m, [38;5;241m2[39m, figsize[38;5;241m=[39m([38;5;241m18[39m, [38;5;241m6[39m))
[0;32m----> 8[0m axs[[38;5;241m0[39m][38;5;241m.[39mimshow([43mmpimg[49m[38;5;241;43m.[39;49m[43mimread[49m[43m([49m[38;5;124;43m'[39;49m[38;5;124;43m./Images/lobes.png[39;49m[38;5;124;43m'[39;49m[43m)[49m)
[1;32m      9[0m axs[[38;5;241m0[39m][38;5;241m.[39mset_axis_off()
[1;32m     10[0m sns[38;5;241m.[39mscatterplot(x[38;5;241m=[39m[38;5;124m"[39m[38;5;124my[39m[38;5;124m"[39m, y[38;5;241m=[39m[38;5;124m"[39m[38;5;124mz[39m[38;5;124m"[39m, data[38;5;241m=[39mcoords_df, hue[38;5;241m=[39m[38;5;124m"[39m[38;5;124mCommunity[39m[38;5;124m"[39m, ax[38;5;241m=[39maxs[[38;5;241m1[39m])

File [0;32m/opt/hostedtoolcache/Python/3.8.13/x64/lib/python3.8/site-packages/matplotlib/image.py:1560[0m, in [0;36mimread[0;34m(fname, format)[0m
[1;32m   1558[0m                 response [38;5;241m=[39m io[38;5;241m.[39mBytesIO(response[38;5;241m.[39mread())
[1;32m   1559[0m             [38;5;28;01mreturn[39;00m imread(response, [38;5;28mformat[39m[38;5;241m=[39mext)
[0;32m-> 1560[0m [38;5;28;01mwith[39;00m [43mimg_open[49m[43m([49m[43mfname[49m[43m)[49m [38;5;28;01mas[39;00m image:
[1;32m   1561[0m     [38;5;28;01mreturn[39;00m (_pil_png_to_float_array(image)
[1;32m   1562[0m             [38;5;28;01mif[39;00m [38;5;28misinstance[39m(image, PIL[38;5;241m.[39mPngImagePlugin[38;5;241m.[39mPngImageFile) [38;5;28;01melse[39;00m
[1;32m   1563[0m             pil_to_array(image))

File [0;32m/opt/hostedtoolcache/Python/3.8.13/x64/lib/python3.8/site-packages/PIL/ImageFile.py:104[0m, in [0;36mImageFile.__init__[0;34m(self, fp, filename)[0m
[1;32m    100[0m [38;5;28mself[39m[38;5;241m.[39mdecodermaxblock [38;5;241m=[39m MAXBLOCK
[1;32m    102[0m [38;5;28;01mif[39;00m is_path(fp):
[1;32m    103[0m     [38;5;66;03m# filename[39;00m
[0;32m--> 104[0m     [38;5;28mself[39m[38;5;241m.[39mfp [38;5;241m=[39m [38;5;28;43mopen[39;49m[43m([49m[43mfp[49m[43m,[49m[43m [49m[38;5;124;43m"[39;49m[38;5;124;43mrb[39;49m[38;5;124;43m"[39;49m[43m)[49m
[1;32m    105[0m     [38;5;28mself[39m[38;5;241m.[39mfilename [38;5;241m=[39m fp
[1;32m    106[0m     [38;5;28mself[39m[38;5;241m.[39m_exclusive_fp [38;5;241m=[39m [38;5;28;01mTrue[39;00m

[0;31mFileNotFoundError[0m: [Errno 2] No such file or directory: './Images/lobes.png'
FileNotFoundError: [Errno 2] No such file or directory: './Images/lobes.png'

