Traceback (most recent call last):
  File "/opt/hostedtoolcache/Python/3.8.12/x64/lib/python3.8/site-packages/jupyter_cache/executors/utils.py", line 51, in single_nb_execution
    executenb(
  File "/opt/hostedtoolcache/Python/3.8.12/x64/lib/python3.8/site-packages/nbclient/client.py", line 1093, in execute
    return NotebookClient(nb=nb, resources=resources, km=km, **kwargs).execute()
  File "/opt/hostedtoolcache/Python/3.8.12/x64/lib/python3.8/site-packages/nbclient/util.py", line 84, in wrapped
    return just_run(coro(*args, **kwargs))
  File "/opt/hostedtoolcache/Python/3.8.12/x64/lib/python3.8/site-packages/nbclient/util.py", line 62, in just_run
    return loop.run_until_complete(coro)
  File "/opt/hostedtoolcache/Python/3.8.12/x64/lib/python3.8/asyncio/base_events.py", line 616, in run_until_complete
    return future.result()
  File "/opt/hostedtoolcache/Python/3.8.12/x64/lib/python3.8/site-packages/nbclient/client.py", line 559, in async_execute
    await self.async_execute_cell(
  File "/opt/hostedtoolcache/Python/3.8.12/x64/lib/python3.8/site-packages/nbclient/client.py", line 854, in async_execute_cell
    self._check_raise_for_error(cell, exec_reply)
  File "/opt/hostedtoolcache/Python/3.8.12/x64/lib/python3.8/site-packages/nbclient/client.py", line 756, in _check_raise_for_error
    raise CellExecutionError.from_cell_and_msg(cell, exec_reply_content)
nbclient.exceptions.CellExecutionError: An error occurred while executing the following cell:
------------------
from graphbook_code import draw_multiplot
from graspologic.plot import heatmap
import matplotlib.pyplot as plt

draw_multiplot(A, title="Simulated RDPG(X)");
------------------

[0;31m---------------------------------------------------------------------------[0m
[0;31mImportError[0m                               Traceback (most recent call last)
[0;32m/tmp/ipykernel_2344/2873174141.py[0m in [0;36m<module>[0;34m[0m
[0;32m----> 1[0;31m [0;32mfrom[0m [0mgraphbook_code[0m [0;32mimport[0m [0mdraw_multiplot[0m[0;34m[0m[0;34m[0m[0m
[0m[1;32m      2[0m [0;32mfrom[0m [0mgraspologic[0m[0;34m.[0m[0mplot[0m [0;32mimport[0m [0mheatmap[0m[0;34m[0m[0;34m[0m[0m
[1;32m      3[0m [0;32mimport[0m [0mmatplotlib[0m[0;34m.[0m[0mpyplot[0m [0;32mas[0m [0mplt[0m[0;34m[0m[0;34m[0m[0m
[1;32m      4[0m [0;34m[0m[0m
[1;32m      5[0m [0mdraw_multiplot[0m[0;34m([0m[0mA[0m[0;34m,[0m [0mtitle[0m[0;34m=[0m[0;34m"Simulated RDPG(X)"[0m[0;34m)[0m[0;34m;[0m[0;34m[0m[0;34m[0m[0m

[0;32m/opt/hostedtoolcache/Python/3.8.12/x64/lib/python3.8/site-packages/graphbook_code/__init__.py[0m in [0;36m<module>[0;34m[0m
[1;32m     26[0m [0;32mfrom[0m [0;34m.[0m[0mutils[0m [0;32mimport[0m [0;34m*[0m[0;34m[0m[0;34m[0m[0m
[1;32m     27[0m [0;32mfrom[0m [0;34m.[0m[0msiem[0m [0;32mimport[0m [0;34m*[0m[0;34m[0m[0;34m[0m[0m
[0;32m---> 28[0;31m [0;32mfrom[0m [0;34m.[0m[0msbm[0m [0;32mimport[0m [0;34m*[0m[0;34m[0m[0;34m[0m[0m
[0m
[0;32m/opt/hostedtoolcache/Python/3.8.12/x64/lib/python3.8/site-packages/graphbook_code/sbm.py[0m in [0;36m<module>[0;34m[0m
[1;32m      7[0m [0;32mfrom[0m [0msklearn[0m[0;34m.[0m[0mutils[0m [0;32mimport[0m [0mcheck_X_y[0m[0;34m[0m[0;34m[0m[0m
[1;32m      8[0m [0;34m[0m[0m
[0;32m----> 9[0;31m [0;32mfrom[0m [0mgraspologic[0m[0;34m.[0m[0mtypes[0m [0;32mimport[0m [0mDict[0m[0;34m,[0m [0mList[0m[0;34m,[0m [0mTuple[0m[0;34m[0m[0;34m[0m[0m
[0m[1;32m     10[0m [0;34m[0m[0m
[1;32m     11[0m [0;32mfrom[0m [0mgraspologic[0m[0;34m.[0m[0mcluster[0m [0;32mimport[0m [0mGaussianCluster[0m[0;34m[0m[0;34m[0m[0m

[0;31mImportError[0m: cannot import name 'Dict' from 'graspologic.types' (/opt/hostedtoolcache/Python/3.8.12/x64/lib/python3.8/site-packages/graspologic/types.py)
ImportError: cannot import name 'Dict' from 'graspologic.types' (/opt/hostedtoolcache/Python/3.8.12/x64/lib/python3.8/site-packages/graspologic/types.py)

