Traceback (most recent call last):
  File "/opt/hostedtoolcache/Python/3.8.13/x64/lib/python3.8/site-packages/jupyter_cache/executors/utils.py", line 51, in single_nb_execution
    executenb(
  File "/opt/hostedtoolcache/Python/3.8.13/x64/lib/python3.8/site-packages/nbclient/client.py", line 1204, in execute
    return NotebookClient(nb=nb, resources=resources, km=km, **kwargs).execute()
  File "/opt/hostedtoolcache/Python/3.8.13/x64/lib/python3.8/site-packages/nbclient/util.py", line 84, in wrapped
    return just_run(coro(*args, **kwargs))
  File "/opt/hostedtoolcache/Python/3.8.13/x64/lib/python3.8/site-packages/nbclient/util.py", line 62, in just_run
    return loop.run_until_complete(coro)
  File "/opt/hostedtoolcache/Python/3.8.13/x64/lib/python3.8/asyncio/base_events.py", line 616, in run_until_complete
    return future.result()
  File "/opt/hostedtoolcache/Python/3.8.13/x64/lib/python3.8/site-packages/nbclient/client.py", line 663, in async_execute
    await self.async_execute_cell(
  File "/opt/hostedtoolcache/Python/3.8.13/x64/lib/python3.8/site-packages/nbclient/client.py", line 965, in async_execute_cell
    await self._check_raise_for_error(cell, cell_index, exec_reply)
  File "/opt/hostedtoolcache/Python/3.8.13/x64/lib/python3.8/site-packages/nbclient/client.py", line 862, in _check_raise_for_error
    raise CellExecutionError.from_cell_and_msg(cell, exec_reply_content)
nbclient.exceptions.CellExecutionError: An error occurred while executing the following cell:
------------------
import numpy as np

fig, axes = plt.subplots(1, len(mols), figsize=(10, 5))
_process = lambda x: [e[0] for e in np.split(x, 2)]
for m_i, m in enumerate(mols):
    num_atoms = m.x.shape[0]
    connectivity_matrix = np.zeros([num_atoms, num_atoms])
    adj_list = m.edge_index.numpy()
    for e_i, (i,j) in enumerate(zip(*_process(adj_list))):
        connectivity_matrix[i, j] = 1
    axes[m_i].imshow(connectivity_matrix)
    axes[m_i].set_title(f'Molecule {m_i+1} adjacency matrix')
    axes[m_i].set_yticks(list(reversed(range(num_atoms))))
    axes[m_i].set_xticks(list(range(num_atoms)))
    axes[m_i].set_xlabel('Atom index')
    axes[m_i].set_ylabel('Atom index')
------------------

[0;31m---------------------------------------------------------------------------[0m
[0;31mNameError[0m                                 Traceback (most recent call last)
Input [0;32mIn [5][0m, in [0;36m<cell line: 3>[0;34m()[0m
[1;32m      1[0m [38;5;28;01mimport[39;00m [38;5;21;01mnumpy[39;00m [38;5;28;01mas[39;00m [38;5;21;01mnp[39;00m
[0;32m----> 3[0m fig, axes [38;5;241m=[39m [43mplt[49m[38;5;241m.[39msubplots([38;5;241m1[39m, [38;5;28mlen[39m(mols), figsize[38;5;241m=[39m([38;5;241m10[39m, [38;5;241m5[39m))
[1;32m      4[0m _process [38;5;241m=[39m [38;5;28;01mlambda[39;00m x: [e[[38;5;241m0[39m] [38;5;28;01mfor[39;00m e [38;5;129;01min[39;00m np[38;5;241m.[39msplit(x, [38;5;241m2[39m)]
[1;32m      5[0m [38;5;28;01mfor[39;00m m_i, m [38;5;129;01min[39;00m [38;5;28menumerate[39m(mols):

[0;31mNameError[0m: name 'plt' is not defined
NameError: name 'plt' is not defined

