Traceback (most recent call last):
  File "/opt/hostedtoolcache/Python/3.8.12/x64/lib/python3.8/site-packages/jupyter_cache/executors/utils.py", line 51, in single_nb_execution
    executenb(
  File "/opt/hostedtoolcache/Python/3.8.12/x64/lib/python3.8/site-packages/nbclient/client.py", line 1117, in execute
    return NotebookClient(nb=nb, resources=resources, km=km, **kwargs).execute()
  File "/opt/hostedtoolcache/Python/3.8.12/x64/lib/python3.8/site-packages/nbclient/util.py", line 78, in wrapped
    return just_run(coro(*args, **kwargs))
  File "/opt/hostedtoolcache/Python/3.8.12/x64/lib/python3.8/site-packages/nbclient/util.py", line 57, in just_run
    return loop.run_until_complete(coro)
  File "/opt/hostedtoolcache/Python/3.8.12/x64/lib/python3.8/asyncio/base_events.py", line 616, in run_until_complete
    return future.result()
  File "/opt/hostedtoolcache/Python/3.8.12/x64/lib/python3.8/site-packages/nbclient/client.py", line 558, in async_execute
    await self.async_execute_cell(
  File "/opt/hostedtoolcache/Python/3.8.12/x64/lib/python3.8/site-packages/nbclient/client.py", line 862, in async_execute_cell
    self._check_raise_for_error(cell, exec_reply)
  File "/opt/hostedtoolcache/Python/3.8.12/x64/lib/python3.8/site-packages/nbclient/client.py", line 765, in _check_raise_for_error
    raise CellExecutionError.from_cell_and_msg(cell, exec_reply_content)
nbclient.exceptions.CellExecutionError: An error occurred while executing the following cell:
------------------
import numpy as np
from graspologic.simulations import sbm
from graspologic.utils import remove_vertices

# Generate parameters
B = np.array([[0.8, 0.2],
              [0.2, 0.8]])

# Generate a network along with community memberships
network, labels = sbm(n=[101, 100], p=B, return_labels=True)
labels = list(labels_)

# Grab out-of-sample vertex
oos_idx = 0
oos_label = labels.pop(oos_idx)
A, a = remove_vertices(network, indices=oos_idx, return_removed=True)
------------------

[0;31m---------------------------------------------------------------------------[0m
[0;31mNameError[0m                                 Traceback (most recent call last)
[0;32m/tmp/ipykernel_1828/1047277327.py[0m in [0;36m<module>[0;34m[0m
[1;32m      9[0m [0;31m# Generate a network along with community memberships[0m[0;34m[0m[0;34m[0m[0;34m[0m[0m
[1;32m     10[0m [0mnetwork[0m[0;34m,[0m [0mlabels[0m [0;34m=[0m [0msbm[0m[0;34m([0m[0mn[0m[0;34m=[0m[0;34m[[0m[0;36m101[0m[0;34m,[0m [0;36m100[0m[0;34m][0m[0;34m,[0m [0mp[0m[0;34m=[0m[0mB[0m[0;34m,[0m [0mreturn_labels[0m[0;34m=[0m[0;32mTrue[0m[0;34m)[0m[0;34m[0m[0;34m[0m[0m
[0;32m---> 11[0;31m [0mlabels[0m [0;34m=[0m [0mlist[0m[0;34m([0m[0mlabels_[0m[0;34m)[0m[0;34m[0m[0;34m[0m[0m
[0m[1;32m     12[0m [0;34m[0m[0m
[1;32m     13[0m [0;31m# Grab out-of-sample vertex[0m[0;34m[0m[0;34m[0m[0;34m[0m[0m

[0;31mNameError[0m: name 'labels_' is not defined
NameError: name 'labels_' is not defined

