Traceback (most recent call last):
  File "/opt/hostedtoolcache/Python/3.8.13/x64/lib/python3.8/site-packages/jupyter_cache/executors/utils.py", line 51, in single_nb_execution
    executenb(
  File "/opt/hostedtoolcache/Python/3.8.13/x64/lib/python3.8/site-packages/nbclient/client.py", line 1204, in execute
    return NotebookClient(nb=nb, resources=resources, km=km, **kwargs).execute()
  File "/opt/hostedtoolcache/Python/3.8.13/x64/lib/python3.8/site-packages/nbclient/util.py", line 84, in wrapped
    return just_run(coro(*args, **kwargs))
  File "/opt/hostedtoolcache/Python/3.8.13/x64/lib/python3.8/site-packages/nbclient/util.py", line 62, in just_run
    return loop.run_until_complete(coro)
  File "/opt/hostedtoolcache/Python/3.8.13/x64/lib/python3.8/asyncio/base_events.py", line 616, in run_until_complete
    return future.result()
  File "/opt/hostedtoolcache/Python/3.8.13/x64/lib/python3.8/site-packages/nbclient/client.py", line 663, in async_execute
    await self.async_execute_cell(
  File "/opt/hostedtoolcache/Python/3.8.13/x64/lib/python3.8/site-packages/nbclient/client.py", line 965, in async_execute_cell
    await self._check_raise_for_error(cell, cell_index, exec_reply)
  File "/opt/hostedtoolcache/Python/3.8.13/x64/lib/python3.8/site-packages/nbclient/client.py", line 862, in _check_raise_for_error
    raise CellExecutionError.from_cell_and_msg(cell, exec_reply_content)
nbclient.exceptions.CellExecutionError: An error occurred while executing the following cell:
------------------
import networkx as nx

fig, axs = plt.subplots(1,2, figsize=(15, 6))

node_names = [i for i in range(1, n+1)]
heatmap(A_bus, ax=axs[0], title="Business Network Adjacency Matrix", xticklabels=node_names, yticklabels=node_names);
axs[0].set_xlabel("Business"); axs[0].set_ylabel("Business");

G_bus = nx.from_numpy_matrix(A_bus)
node_pos = nx.shell_layout(G_bus)
nx.draw(G, pos=node_pos, ax=axs[1])
axs[1].set_title("Business Network Layout Plot");
------------------

[0;31m---------------------------------------------------------------------------[0m
[0;31mNameError[0m                                 Traceback (most recent call last)
Input [0;32mIn [4][0m, in [0;36m<cell line: 11>[0;34m()[0m
[1;32m      9[0m G_bus [38;5;241m=[39m nx[38;5;241m.[39mfrom_numpy_matrix(A_bus)
[1;32m     10[0m node_pos [38;5;241m=[39m nx[38;5;241m.[39mshell_layout(G_bus)
[0;32m---> 11[0m nx[38;5;241m.[39mdraw([43mG[49m, pos[38;5;241m=[39mnode_pos, ax[38;5;241m=[39maxs[[38;5;241m1[39m])
[1;32m     12[0m axs[[38;5;241m1[39m][38;5;241m.[39mset_title([38;5;124m"[39m[38;5;124mBusiness Network Layout Plot[39m[38;5;124m"[39m)

[0;31mNameError[0m: name 'G' is not defined
NameError: name 'G' is not defined

