Traceback (most recent call last):
  File "/opt/hostedtoolcache/Python/3.8.12/x64/lib/python3.8/site-packages/jupyter_cache/executors/utils.py", line 51, in single_nb_execution
    executenb(
  File "/opt/hostedtoolcache/Python/3.8.12/x64/lib/python3.8/site-packages/nbclient/client.py", line 1093, in execute
    return NotebookClient(nb=nb, resources=resources, km=km, **kwargs).execute()
  File "/opt/hostedtoolcache/Python/3.8.12/x64/lib/python3.8/site-packages/nbclient/util.py", line 84, in wrapped
    return just_run(coro(*args, **kwargs))
  File "/opt/hostedtoolcache/Python/3.8.12/x64/lib/python3.8/site-packages/nbclient/util.py", line 62, in just_run
    return loop.run_until_complete(coro)
  File "/opt/hostedtoolcache/Python/3.8.12/x64/lib/python3.8/asyncio/base_events.py", line 616, in run_until_complete
    return future.result()
  File "/opt/hostedtoolcache/Python/3.8.12/x64/lib/python3.8/site-packages/nbclient/client.py", line 559, in async_execute
    await self.async_execute_cell(
  File "/opt/hostedtoolcache/Python/3.8.12/x64/lib/python3.8/site-packages/nbclient/client.py", line 854, in async_execute_cell
    self._check_raise_for_error(cell, exec_reply)
  File "/opt/hostedtoolcache/Python/3.8.12/x64/lib/python3.8/site-packages/nbclient/client.py", line 756, in _check_raise_for_error
    raise CellExecutionError.from_cell_and_msg(cell, exec_reply_content)
nbclient.exceptions.CellExecutionError: An error occurred while executing the following cell:
------------------
from graspologic.simulations import sbm
from matplotlib import pyplot as plt
from graphbook_code import heatmap
from numpy.random import beta

wtargsh = [[dict(a=8, b=1), dict(a=2, b=10)],
          [dict(a=2, b=2), dict(a=8, b=1)]]

wtargsa = [[dict(lam=10), dict(lam=5)],
          [dict(lam=5), dict(lam=10)]]

# human brain network
Ah = sbm(n=[3,3], p=[[1,1], [1,1]], wt=beta, wtargs=wtargsh, loops=False, directed=True)

# alien brain network
Aa = sbm(n=[3,3], p=[[1, 1], [1, 1]], wt=poisson, wtargs=wtargsa, directed=False)
------------------

[0;31m---------------------------------------------------------------------------[0m
[0;31mNameError[0m                                 Traceback (most recent call last)
[0;32m/tmp/ipykernel_2128/1663019045.py[0m in [0;36m<module>[0;34m[0m
[1;32m     14[0m [0;34m[0m[0m
[1;32m     15[0m [0;31m# alien brain network[0m[0;34m[0m[0;34m[0m[0;34m[0m[0m
[0;32m---> 16[0;31m [0mAa[0m [0;34m=[0m [0msbm[0m[0;34m([0m[0mn[0m[0;34m=[0m[0;34m[[0m[0;36m3[0m[0;34m,[0m[0;36m3[0m[0;34m][0m[0;34m,[0m [0mp[0m[0;34m=[0m[0;34m[[0m[0;34m[[0m[0;36m1[0m[0;34m,[0m [0;36m1[0m[0;34m][0m[0;34m,[0m [0;34m[[0m[0;36m1[0m[0;34m,[0m [0;36m1[0m[0;34m][0m[0;34m][0m[0;34m,[0m [0mwt[0m[0;34m=[0m[0mpoisson[0m[0;34m,[0m [0mwtargs[0m[0;34m=[0m[0mwtargsa[0m[0;34m,[0m [0mdirected[0m[0;34m=[0m[0;32mFalse[0m[0;34m)[0m[0;34m[0m[0;34m[0m[0m
[0m
[0;31mNameError[0m: name 'poisson' is not defined
NameError: name 'poisson' is not defined

